Workbook

Sheet Reponses
A1: TP1 - | C1: (groupe E14)
A2: Exercice 1
A3: 1.A Courbe de puissance en fonction du temps (données de la feuille E14)
A25: 1.B : estimation sur la courbe
A26: lecture du début de l’IA sur le graphique :
A43: lecture de la fin de l’IA sur le graphique :
A61: A partir du fichier AI_executions_on_sut16 on a :
B62: Ligne du log | C62: Timestamp
B63: Start of power monitor | C63: 1736676735655
B64: Start of AI executions | C64: 1736676855674
B65: End of AI executions | C65: 1736676935795
A67: Calculs et formules :
B68: Durée de l’IA (ms) = End of AI executions - Start of AI executions = 80121 ms
B69: Durée de l’IA (s) = Durée de l’IA (ms) / 1000 = 80.121 s
B70: Début de l’IA sur la courbe (s) = (Start of AI executions - Start of power monitor) / 1000 = 120.019 s
A72: Conclusion 1.B : Sur la courbe, l’exécution de l’IA dure environ 80 s, de 120 s à 200 s. Le calcul exact avec le log donne 80,121 s (80 121 ms). L’estimation est donc cohérente avec le calcul précis.
A75: 1.C : puissance moyenne de la carte sans l'exécution IA :
B76: Début de l’IA (ms) =(Start of AI executions − Start of power monitor) = 1736676855674 − 1736676735655 = 120 019 ms
B77: Fin de l’IA (ms) = End of AI executions - Start of power monitor = 1736676935795 - 1736676735655 = 200 140 ms
A79: calcul : le CSV a un point toutes les 100 ms, de 0 à 359 900 ms, soit 3600 points.
B80: Période | C80: Nombre de points | D80: Somme des puissances (W)
B81: Avant l’IA (t < 120 019 ms) | C81: 1201 | D81: 345680
B82: Après l’IA (t > 200 140 ms) | C82: 1598 | D82: 467830
B83: Total hors IA | C83: 2799 | D83: 813510
A85: Formule :
B86: Pmoyenne = (Somme des puissances avant IA + Somme des puissances aprés IA) / (Nombre de points avant + Nombre de points aprés)
A87: A.N : | B87: Pmoyenne = Somme des puissances / Nombre de points = 0.291 W
B88: On constate que sans l'éxécution IA , la puissance moynne de la carte Rassberry PI est d'environ 0,29 W . Cette valeur correspond aux taches classiques du systéme d'éxploitation
A90: 1.D : Calculer la puissance moyenne en W de la carte Raspberry Pi uniquement due l'exécution :
A91: Pour avoir seulement la part de l’IA, on enlève la puissance de l’OS trouvée en 1.C
A93: 1- trouver les lignes :
B94: Avant l’IA : de t = 0 à 120 000 ms, lignes 2 à 1202.
B95: Pendant l’IA : de t = 120 100 à 200 100 ms, lignes 1203 à 2003.
B96: Après l’IA (t de 200 200 à 359 900 ms) : lignes 2003 à 3600
A98: 2- Formules de calculs : | C98: Pendant l’IA (OS + IA) = | D98: =AVERAGE('E14'!B1202:B2002) -> 0.67606991
C99: OS seul = | D99: =AVERAGE(B1:B1174,B1976:B3573) -> 0.3205847
C100: IA seule = Pendant l’IA (OS + IA) - OS seul = | D100: =D98-D99 -> 0.35548522
A103: 1.E : empreinte carbone de l’exécution IA :
B104: Données :
B105: Puissance de l’IA seule = 0,3854 W
...

Sheet LOG
A1: 45669 | B1: 0.41187966 | C1: 1736671986403 | D1: E1 Start of power monitor
A2: 45669 | B2: 0.41326885 | C2: 1736672106429 | D2: E1 Start of AI executions
A3: 45669 | B3: 0.41491646 | C3: 1736672248782 | D3: E1 End of AI executions
A4: 45669 | B4: 0.41605433 | C4: 1736672347094 | D4: E1 End of power monitor
A5: 45669 | B5: 0.41605444 | C5: 1736672347104 | D5: E2 Start of power monitor
A6: 45669 | B6: 0.41744354 | C6: 1736672467122 | D6: E2 Start of AI executions
A7: 45669 | B7: 0.41845301 | C7: 1736672554340 | D7: E2 End of AI executions
A8: 45669 | B8: 0.42022858 | C8: 1736672707749 | D8: E2 End of power monitor
A9: 45669 | B9: 0.4202287 | C9: 1736672707760 | D9: E3 Start of power monitor
A10: 45669 | B10: 0.4216178 | C10: 1736672827778 | D10: E3 Start of AI executions
A11: 45669 | B11: 0.42229468 | C11: 1736672886260 | D11: E3 End of AI executions
A12: 45669 | B12: 0.424403 | C12: 1736673068419 | D12: E3 End of power monitor
... A84: 45669 | B84: 0.50024126 | C84: 1736679620845 | D84: E21 End of power monitor

Sheet E1
A1: 0 | B1: 0.288 | C1: 375.2 | D1: 0.772
A2: 100 | B2: 0.286 | C2: 375.5 | D2: 0.76
A3: 200 | B3: 0.288 | C3: 375.3 | D3: 0.764
A4: 300 | B4: 0.288 | C4: 375.2 | D4: 0.772
A5: 400 | B5: 0.292 | C5: 375.4 | D5: 0.776
A6: 500 | B6: 0.288 | C6: 375.3 | D6: 0.768
A7: 600 | B7: 0.286 | C7: 375.3 | D7: 0.76
A8: 700 | B8: 0.282 | C8: 375.4 | D8: 0.752
A9: 800 | B9: 0.278 | C9: 375.2 | D9: 0.744
A10: 900 | B10: 0.276 | C10: 375.2 | D10: 0.736
A11: 1000 | B11: 0.278 | C11: 375.4 | D11: 0.74
A12: 1100 | B12: 0.278 | C12: 375.3 | D12: 0.74
... A3600: 359900 | B3600: 0.288 | C3600: 379.9 | D3600: 0.76

Sheet E2
A1: 0 | B1: 0.288 | C1: 379.7 | D1: 0.756
A2: 100 | B2: 0.288 | C2: 379.6 | D2: 0.76
A3: 200 | B3: 0.292 | C3: 379.6 | D3: 0.764
A4: 300 | B4: 0.292 | C4: 379.9 | D4: 0.768
A5: 400 | B5: 0.292 | C5: 379.6 | D5: 0.768
A6: 500 | B6: 0.288 | C6: 379.6 | D6: 0.756
A7: 600 | B7: 0.292 | C7: 379.7 | D7: 0.748
A8: 700 | B8: 0.282 | C8: 379.6 | D8: 0.74
A9: 800 | B9: 0.278 | C9: 379.6 | D9: 0.732
A10: 900 | B10: 0.278 | C10: 379.6 | D10: 0.732
A11: 1000 | B11: 0.282 | C11: 379.6 | D11: 0.74
A12: 1100 | B12: 0.288 | C12: 379.6 | D12: 0.744
... A3600: 359900 | B3600: 0.278 | C3600: 378.2 | D3600: 0.732

Sheet E3
A1: 0 | B1: 0.286 | C1: 378.6 | D1: 0.76
A2: 100 | B2: 0.282 | C2: 378.2 | D2: 0.748
A3: 200 | B3: 0.278 | C3: 378.3 | D3: 0.736
A4: 300 | B4: 0.276 | C4: 378.2 | D4: 0.732
A5: 400 | B5: 0.278 | C5: 378.2 | D5: 0.736
A6: 500 | B6: 0.282 | C6: 378.4 | D6: 0.744
A7: 600 | B7: 0.282 | C7: 378.3 | D7: 0.748
A8: 700 | B8: 0.314 | C8: 418.8 | D8: 0.752
A9: 800 | B9: 0.288 | C9: 378.2 | D9: 0.764
A10: 900 | B10: 0.292 | C10: 378.2 | D10: 0.768
A11: 1000 | B11: 0.292 | C11: 378.3 | D11: 0.772
A12: 1100 | B12: 0.288 | C12: 378.2 | D12: 0.764
... A3600: 359900 | B3600: 0.288 | C3600: 377.9 | D3600: 0.768

Sheet E4
A1: 0 | B1: 0.282 | C1: 377.3 | D1: 0.748
A2: 100 | B2: 0.286 | C2: 377.4 | D2: 0.752
A3: 200 | B3: 0.288 | C3: 377.5 | D3: 0.76
A4: 300 | B4: 0.288 | C4: 377.6 | D4: 0.764
A5: 400 | B5: 0.292 | C5: 377.7 | D5: 0.768
A6: 500 | B6: 0.288 | C6: 377.7 | D6: 0.764
A7: 600 | B7: 0.286 | C7: 377.6 | D7: 0.752
A8: 700 | B8: 0.282 | C8: 377.4 | D8: 0.744
A9: 800 | B9: 0.276 | C9: 377.3 | D9: 0.732
A10: 900 | B10: 0.276 | C10: 377.3 | D10: 0.732
A11: 1000 | B11: 0.278 | C11: 377.3 | D11: 0.736
A12: 1100 | B12: 0.278 | C12: 377.3 | D12: 0.74
... A3600: 359900 | B3600: 0.288 | C3600: 377.7 | D3600: 0.764

Sheet E5
A1: 0 | B1: 0.288 | C1: 377.6 | D1: 0.76
A2: 100 | B2: 0.288 | C2: 377.7 | D2: 0.744
A3: 200 | B3: 0.292 | C3: 390.2 | D3: 0.748
A4: 300 | B4: 0.292 | C4: 378.1 | D4: 0.752
A5: 400 | B5: 0.288 | C5: 377.8 | D5: 0.76
A6: 500 | B6: 0.288 | C6: 377.4 | D6: 0.764
A7: 600 | B7: 0.288 | C7: 377.4 | D7: 0.768
A8: 700 | B8: 0.292 | C8: 380.1 | D8: 0.768
A9: 800 | B9: 0.288 | C9: 377.5 | D9: 0.76
A10: 900 | B10: 0.286 | C10: 377.5 | D10: 0.752
A11: 1000 | B11: 0.282 | C11: 377.5 | D11: 0.744
A12: 1100 | B12: 0.278 | C12: 377.3 | D12: 0.736
... A3600: 359900 | B3600: 0.748 | C3600: 1068.3 | D3600: 0.7

Sheet E6
A1: 0 | B1: 0.396 | C1: 515 | D1: 0.772
A2: 100 | B2: 0.386 | C2: 514.7 | D2: 0.748
A3: 200 | B3: 0.384 | C3: 514.3 | D3: 0.744
A4: 300 | B4: 0.38 | C4: 514.1 | D4: 0.736
A5: 400 | B5: 0.374 | C5: 513.9 | D5: 0.728
A6: 500 | B6: 0.37 | C6: 513.7 | D6: 0.72
A7: 600 | B7: 0.37 | C7: 513.5 | D7: 0.72
A8: 700 | B8: 0.374 | C8: 513.2 | D8: 0.728
A9: 800 | B9: 0.376 | C9: 513.2 | D9: 0.732
A10: 900 | B10: 0.376 | C10: 513 | D10: 0.736
A11: 1000 | B11: 0.384 | C11: 512.6 | D11: 0.74
A12: 1100 | B12: 0.38 | C12: 512.6 | D12: 0.744
... A3600: 359900 | B3600: 0.286 | C3600: 388.3 | D3600: 0.768

Sheet E7
A1: 0 | B1: E6 | C1: 388.9 | D1: 0.764
A2: 100 | B2: 0.294 | C2: 388.5 | D2: 0.756
A3: 200 | B3: 0.298 | C3: 388.9 | D3: 0.748
A4: 300 | B4: 0.294 | C4: 395.9 | D4: 0.74
A5: 400 | B5: 0.286 | C5: 388.3 | D5: 0.732
A6: 500 | B6: 0.304 | C6: 424.2 | D6: 0.728
A7: 600 | B7: 0.286 | C7: 388.2 | D7: 0.736
A8: 700 | B8: 0.294 | C8: 388 | D8: 0.74
A9: 800 | B9: 0.288 | C9: 388.1 | D9: 0.744
A10: 900 | B10: 0.292 | C10: 388.1 | D10: 0.748
A11: 1000 | B11: 0.294 | C11: 388.7 | D11: 0.756
A12: 1100 | B12: 0.294 | C12: 388.3 | D12: 0.76
A13: 1200 | B13: 0.304 | C13: 388.1 | D13: 0.764
... A3600: 359900 | B3600: 0.292 | C3600: 387.1 | D3600: 0.768

Sheet E8
A1: 0 | B1: 0.286 | C1: 379.2 | D1: 0.752
A2: 100 | B2: 0.286 | C2: 378.9 | D2: 0.756
A3: 200 | B3: 0.292 | C3: 378.9 | D3: 0.768
A4: 300 | B4: 0.292 | C4: 378.8 | D4: 0.768
A5: 400 | B5: 0.292 | C5: 379 | D5: 0.772
A6: 500 | B6: 0.292 | C6: 379 | D6: 0.768
A7: 600 | B7: 0.288 | C7: 379.3 | D7: 0.76
A8: 700 | B8: 0.286 | C8: 379.2 | D8: 0.752
A9: 800 | B9: 0.288 | C9: 387.4 | D9: 0.744
A10: 900 | B10: 0.278 | C10: 378.8 | D10: 0.736
A11: 1000 | B11: 0.282 | C11: 378.8 | D11: 0.74
A12: 1100 | B12: 0.282 | C12: 378.8 | D12: 0.74
... A3600: 359900 | B3600: 0.282 | C3600: 380.1 | D3600: 0.744

Sheet E9
A1: 0 | B1: 0.292 | C1: 380.2 | D1: 0.768
A2: 100 | B2: 0.292 | C2: 380.1 | D2: 0.768
A3: 200 | B3: 0.288 | C3: 380.1 | D3: 0.756
A4: 300 | B4: 0.286 | C4: 380.2 | D4: 0.748
A5: 400 | B5: 0.282 | C5: 380.2 | D5: 0.74
A6: 500 | B6: 0.278 | C6: 380.1 | D6: 0.732
A7: 600 | B7: 0.282 | C7: 381.1 | D7: 0.736
A8: 700 | B8: 0.282 | C8: 380.2 | D8: 0.74
A9: 800 | B9: 0.282 | C9: 380.4 | D9: 0.744
A10: 900 | B10: 0.286 | C10: 380.1 | D10: 0.748
A11: 1000 | B11: 0.288 | C11: 380.2 | D11: 0.756
A12: 1100 | B12: 0.288 | C12: 380.1 | D12: 0.76
... A3600: 359900 | B3600: 0.282 | C3600: 377.8 | D3600: 0.744

Sheet E10
A1: 0 | B1: 0.286 | C1: 377.3 | D1: 0.756
A2: 100 | B2: 0.276 | C2: 377.8 | D2: 0.732
A3: 200 | B3: 0.278 | C3: 377.9 | D3: 0.736
A4: 300 | B4: 0.278 | C4: 377.7 | D4: 0.74
A5: 400 | B5: 0.278 | C5: 377.8 | D5: 0.74
A6: 500 | B6: 0.282 | C6: 377.9 | D6: 0.748
A7: 600 | B7: 0.286 | C7: 377.9 | D7: 0.752
A8: 700 | B8: 0.288 | C8: 377.8 | D8: 0.76
A9: 800 | B9: 0.288 | C9: 377.8 | D9: 0.76
A10: 900 | B10: 0.294 | C10: 413.6 | D10: 0.764
A11: 1000 | B11: 0.292 | C11: 377.8 | D11: 0.772
A12: 1100 | B12: 0.294 | C12: 377.9 | D12: 0.768
... A3600: 359900 | B3600: 0.282 | C3600: 377.4 | D3600: 0.744

Sheet E11
A1: 0 | B1: 0.292 | C1: 377.7 | D1: 0.768
A2: 100 | B2: 0.282 | C2: 377.4 | D2: 0.748
A3: 200 | B3: 0.304 | C3: 413.1 | D3: 0.736
A4: 300 | B4: 0.278 | C4: 377.3 | D4: 0.736
A5: 400 | B5: 0.278 | C5: 377.5 | D5: 0.74
A6: 500 | B6: 0.278 | C6: 377.3 | D6: 0.74
A7: 600 | B7: 0.282 | C7: 377.2 | D7: 0.748
A8: 700 | B8: 0.286 | C8: 377.3 | D8: 0.752
A9: 800 | B9: 0.288 | C9: 377.4 | D9: 0.76
A10: 900 | B10: 0.288 | C10: 378.7 | D10: 0.76
A11: 1000 | B11: 0.288 | C11: 377.3 | D11: 0.764
A12: 1100 | B12: 0.292 | C12: 377.3 | D12: 0.772
... A3600: 359900 | B3600: 0.278 | C3600: 377.1 | D3600: 0.74

Sheet E12
A1: 0 | B1: 0.288 | C1: 377.1 | D1: 0.768
A2: 100 | B2: 0.286 | C2: 377.2 | D2: 0.76
A3: 200 | B3: 0.286 | C3: 377.3 | D3: 0.752
A4: 300 | B4: 0.282 | C4: 377.1 | D4: 0.744
A5: 400 | B5: 0.278 | C5: 377.1 | D5: 0.736
A6: 500 | B6: 0.278 | C6: 377.1 | D6: 0.736
A7: 600 | B7: 0.278 | C7: 377.1 | D7: 0.74
A8: 700 | B8: 0.278 | C8: 377.2 | D8: 0.74
A9: 800 | B9: 0.282 | C9: 377.1 | D9: 0.748
A10: 900 | B10: 0.286 | C10: 377.6 | D10: 0.756
A11: 1000 | B11: 0.286 | C11: 377.1 | D11: 0.76
A12: 1100 | B12: 0.288 | C12: 377.1 | D12: 0.768
... A3600: 359900 | B3600: 0.286 | C3600: 377 | D3600: 0.76

Sheet E13
A1: 0 | B1: 0.286 | C1: 377 | D1: 0.756
A2: 100 | B2: 0.282 | C2: 377 | D2: 0.752
A3: 200 | B3: 0.282 | C3: 377 | D3: 0.772
A4: 300 | B4: 0.292 | C4: 377.3 | D4: 0.772
A5: 400 | B5: 0.288 | C5: 377 | D5: 0.764
A6: 500 | B6: 0.286 | C6: 377.1 | D6: 0.756
A7: 600 | B7: 0.282 | C7: 377 | D7: 0.748
A8: 700 | B8: 0.278 | C8: 377.2 | D8: 0.74
A9: 800 | B9: 0.278 | C9: 377 | D9: 0.74
A10: 900 | B10: 0.278 | C10: 377 | D10: 0.74
A11: 1000 | B11: 0.282 | C11: 377 | D11: 0.744
A12: 1100 | B12: 0.282 | C12: 377.1 | D12: 0.748
... A3600: 359900 | B3600: 0.282 | C3600: 376.8 | D3600: 0.748

Sheet E14
A1: 0 | B1: 0.298 | C1: 376.7 | D1: 0.788
A2: 100 | B2: 0.292 | C2: 376.8 | D2: 0.772
A3: 200 | B3: 0.288 | C3: 377 | D3: 0.768
A4: 300 | B4: 0.286 | C4: 377.1 | D4: 0.76
A5: 400 | B5: 0.282 | C5: 377.2 | D5: 0.748
A6: 500 | B6: 0.278 | C6: 377.2 | D6: 0.74
A7: 600 | B7: 0.302 | C7: 413 | D7: 0.732
A8: 700 | B8: 0.278 | C8: 376.9 | D8: 0.74
A9: 800 | B9: 0.282 | C9: 376.9 | D9: 0.744
A10: 900 | B10: 0.282 | C10: 376.8 | D10: 0.744
A11: 1000 | B11: 0.282 | C11: 378.5 | D11: 0.752
A12: 1100 | B12: 0.286 | C12: 382.8 | D12: 0.756
... A3600: 359900 | B3600: 0.292 | C3600: 377.5 | D3600: 0.772

Sheet E15
A1: 0 | B1: 0.292 | C1: 385.9 | D1: 0.772
A2: 100 | B2: 0.292 | C2: 379.1 | D2: 0.768
A3: 200 | B3: 0.286 | C3: 377.7 | D3: 0.756
A4: 300 | B4: 0.282 | C4: 377.7 | D4: 0.748
A5: 400 | B5: 0.278 | C5: 377.6 | D5: 0.74
A6: 500 | B6: 0.278 | C6: 386.1 | D6: 0.736
A7: 600 | B7: 0.278 | C7: 377.5 | D7: 0.74
A8: 700 | B8: 0.282 | C8: 377.5 | D8: 0.744
A9: 800 | B9: 0.282 | C9: 377.6 | D9: 0.748
A10: 900 | B10: 0.286 | C10: 377.6 | D10: 0.752
A11: 1000 | B11: 0.286 | C11: 385.8 | D11: 0.756
A12: 1100 | B12: 0.288 | C12: 387.7 | D12: 0.76
... A3600: 359900 | B3600: 0.288 | C3600: 377.2 | D3600: 0.768

Sheet E16
A1: 0 | B1: 0.288 | C1: 377.5 | D1: 0.768
A2: 100 | B2: 0.286 | C2: 377.6 | D2: 0.76
A3: 200 | B3: 0.286 | C3: 377.7 | D3: 0.756
A4: 300 | B4: 0.282 | C4: 377.6 | D4: 0.744
A5: 400 | B5: 0.286 | C5: 377.2 | D5: 0.736
A6: 500 | B6: 0.278 | C6: 377.2 | D6: 0.74
A7: 600 | B7: 0.282 | C7: 379 | D7: 0.744
A8: 700 | B8: 0.282 | C8: 377.3 | D8: 0.744
A9: 800 | B9: 0.282 | C9: 377.3 | D9: 0.732
A10: 900 | B10: 0.294 | C10: 377.3 | D10: 0.736
A11: 1000 | B11: 0.286 | C11: 377.2 | D11: 0.74
A12: 1100 | B12: 0.282 | C12: 377.8 | D12: 0.744
... A3600: 359900 | B3600: 0.318 | C3600: 432.4 | D3600: 0.768

Sheet E17
A1: 0 | B1: 0.328 | C1: 429.9 | D1: 0.764
A2: 100 | B2: 0.328 | C2: 430 | D2: 0.76
A3: 200 | B3: 0.322 | C3: 429.6 | D3: 0.748
A4: 300 | B4: 0.288 | C4: 387.3 | D4: 0.744
A5: 400 | B5: 0.278 | C5: 377.1 | D5: 0.736
A6: 500 | B6: 0.276 | C6: 377.2 | D6: 0.732
A7: 600 | B7: 0.278 | C7: 377.2 | D7: 0.736
A8: 700 | B8: 0.278 | C8: 377.2 | D8: 0.74
A9: 800 | B9: 0.286 | C9: 385.2 | D9: 0.744
A10: 900 | B10: 0.286 | C10: 377.4 | D10: 0.752
A11: 1000 | B11: 0.286 | C11: 412.9 | D11: 0.756
A12: 1100 | B12: 0.292 | C12: 377.1 | D12: 0.764
... A3600: 359900 | B3600: 0.278 | C3600: 377.5 | D3600: 0.736

Sheet E18
A1: 0 | B1: 0.292 | C1: 377.8 | D1: 0.772
A2: 100 | B2: 0.286 | C2: 379.1 | D2: 0.752
A3: 200 | B3: 0.282 | C3: 413.6 | D3: 0.74
A4: 300 | B4: 0.286 | C4: 377.9 | D4: 0.736
A5: 400 | B5: 0.278 | C5: 377.9 | D5: 0.74
A6: 500 | B6: 0.282 | C6: 377.4 | D6: 0.744
A7: 600 | B7: 0.282 | C7: 388.6 | D7: 0.748
A8: 700 | B8: 0.286 | C8: 377.5 | D8: 0.752
A9: 800 | B9: 0.286 | C9: 377.5 | D9: 0.756
A10: 900 | B10: 0.288 | C10: 377.5 | D10: 0.764
A11: 1000 | B11: 0.288 | C11: 377.5 | D11: 0.768
A12: 1100 | B12: 0.292 | C12: 396.2 | D12: 0.768
... A3600: 359900 | B3600: 0.292 | C3600: 377.8 | D3600: 0.768

Sheet E19
A1: 0 | B1: 0.286 | C1: 377.4 | D1: 0.756
A2: 100 | B2: 0.288 | C2: 377.5 | D2: 0.768
A3: 200 | B3: 0.292 | C3: 377.5 | D3: 0.772
A4: 300 | B4: 0.292 | C4: 377.5 | D4: 0.772
A5: 400 | B5: 0.288 | C5: 377.5 | D5: 0.764
A6: 500 | B6: 0.288 | C6: 380 | D6: 0.756
A7: 600 | B7: 0.282 | C7: 377.5 | D7: 0.744
A8: 700 | B8: 0.278 | C8: 377.5 | D8: 0.736
A9: 800 | B9: 0.278 | C9: 377.5 | D9: 0.74
A10: 900 | B10: 0.282 | C10: 377.5 | D10: 0.744
A11: 1000 | B11: 0.288 | C11: 386 | D11: 0.744
A12: 1100 | B12: 0.282 | C12: 377.6 | D12: 0.748
... A3600: 359900 | B3600: 0.288 | C3600: 377.6 | D3600: 0.768

Sheet E20
A1: 0 | B1: 0.288 | C1: 377.5 | D1: 0.748
A2: 100 | B2: 0.286 | C2: 377.3 | D2: 0.752
A3: 200 | B3: 0.288 | C3: 377.6 | D3: 0.76
A4: 300 | B4: 0.288 | C4: 377.6 | D4: 0.764
A5: 400 | B5: 0.292 | C5: 377.6 | D5: 0.768
A6: 500 | B6: 0.292 | C6: 377.7 | D6: 0.768
A7: 600 | B7: 0.288 | C7: 377.4 | D7: 0.76
A8: 700 | B8: 0.286 | C8: 377.3 | D8: 0.752
A9: 800 | B9: 0.282 | C9: 377.5 | D9: 0.744
A10: 900 | B10: 0.278 | C10: 377.4 | D10: 0.736
A11: 1000 | B11: 0.276 | C11: 377.4 | D11: 0.732
A12: 1100 | B12: 0.278 | C12: 377.3 | D12: 0.736
... A3600: 359900 | B3600: 0.288 | C3600: 390.7 | D3600: 0.736

Sheet E21
A1: 0 | B1: 0.282 | C1: 379.3 | D1: 0.74
A2: 100 | B2: 0.278 | C2: 379 | D2: 0.736
A3: 200 | B3: 0.282 | C3: 378.8 | D3: 0.74
A4: 300 | B4: 0.282 | C4: 378.9 | D4: 0.74
A5: 400 | B5: 0.282 | C5: 379 | D5: 0.748
A6: 500 | B6: 0.286 | C6: 378.9 | D6: 0.752
A7: 600 | B7: 0.286 | C7: 379 | D7: 0.756
A8: 700 | B8: 0.314 | C8: 414.6 | D8: 0.756
A9: 800 | B9: 0.298 | C9: 378.8 | D9: 0.764
A10: 900 | B10: 0.292 | C10: 378.7 | D10: 0.768
A11: 1000 | B11: 0.288 | C11: 378.8 | D11: 0.764
A12: 1100 | B12: 0.286 | C12: 378.8 | D12: 0.756
... A3600: 359900 | B3600: 0.304 | C3600: 379.4 | D3600: 0.768
