Workbook

Sheet Log
A1: Exécution | B1: Start of power monitor (ms) | C1: Start of AI executions (ms) | D1: End of AI executions (ms) | E1: End of power monitor (ms) | F1: Début IA relatif (ms) | G1: Fin IA relative (ms) | H1: Durée IA (ms) | I1: Durée IA (s) | K1: Exécution | L1: Début du traitement IA (AI_executions.log) | M1: Fin du traitement IA (AI_executions.log) | N1: Temps d'exécution IA (ms) | O1: Réponse de l'IA | P1: Réponse correcte ? (Oui/Non)
A2: E1 | B2: 1736671986403 | C2: 1736672106429 | D2: 1736672248782 | E2: 1736672347094 | F2: =C2-B2 -> 120026 | G2: =D2-B2 -> 262379 | H2: =D2-C2 -> 142353 | I2: =H2/1000 -> 142.353 | K2: E1 | L2: 2025-01-12 09:55:18.081422 | M2: 2025-01-12 09:55:20.562540 | N2: 2481.0996 | O2: I'm happy to help you with that! However, I need a bit more information from you. France is a country, and it's not clear what specific city or region you're referring to. | P2: Non
A3: E2 | B3: 1736672347104 | C3: 1736672467122 | D3: 1736672554340 | E3: 1736672707749 | F3: =C3-B3 -> 120018 | G3: =D3-B3 -> 207236 | H3: =D3-C3 -> 87218 | I3: =H3/1000 -> 87.218 | K3: E2 | L3: 2025-01-12 10:01:18.818720 | M3: 2025-01-12 10:01:21.253245 | N3: 2434.5081 | O3: I'm sorry, but I don't have a list. There isn't a list. | P3: Non
A4: E3 | B4: 1736672707760 | C4: 1736672827778 | D4: 1736672886260 | E4: 1736673068419 | F4: =C4-B4 -> 120018 | G4: =D4-B4 -> 178500 | H4: =D4-C4 -> 58482 | I4: =H4/1000 -> 58.482 | K4: E3 | L4: 2025-01-12 10:07:19.875759 | M4: 2025-01-12 10:07:22.354493 | N4: 2478.7159 | O4: The capital in France is Paris. | P4: Oui
A5: E4 | B5: 1736673068430 | C5: 1736673188448 | D5: 1736673258624 | E5: 1736673429079 | F5: =C5-B5 -> 120018 | G5: =D5-B5 -> 190194 | H5: =D5-C5 -> 70176 | I5: =H5/1000 -> 70.176 | K5: E4 | L5: 2025-01-12 10:13:20.120257 | M5: 2025-01-12 10:13:22.555442 | N5: 2435.1664 | O5: That is incorrect. The capital of France is Paris. | P5: Oui
A6: E5 | B6: 1736673429090 | C6: 1736673549108 | D6: 1736673850353 | E6: 1736673850367 | F6: =C6-B6 -> 120018 | G6: =D6-B6 -> 421263 | H6: =D6-C6 -> 301245 | I6: =H6/1000 -> 301.245 | K6: E5 | L6: 2025-01-12 10:19:21.167950 | M6: 2025-01-12 10:19:23.613455 | N6: 2445.4868 | O6: I'm happy to help you with your question, but I'm a large language model, I don't have personal preferences, emotions, or consciousness like a human. I can provide you with information on human topics such as the capital in France, but I cannot participate in a conversation. How can I assist you today? You can also ask me to provide you with information in different ways such as, - Answering questions - Providing examples - Offering suggestions - Generating text - Translating text | P6: Non
A7: E6 | B7: 1736673850388 | C7: 1736673970418 | D7: 1736674172339 | E7: 1736674211103 | F7: =C7-B7 -> 120030 | G7: =D7-B7 -> 321951 | H7: =D7-C7 -> 201921 | I7: =H7/1000 -> 201.921 | K7: E6 | L7: 2025-01-12 10:26:22.079301 | M7: 2025-01-12 10:26:24.535648 | N7: 2456.3274 | O7: You are correct, the capital of France is Paris. However, I made an incorrect assumption, you didn't provide the word in French where it is mentioned to. If that is the case, I would have said that the word is "Parr" but I didn't provide it because it wasn't asked. | P7: Oui
A8: E7 | B8: 1736674211114 | C8: 1736674331132 | D8: 1736674384450 | E8: 1736674571765 | F8: =C8-B8 -> 120018 | G8: =D8-B8 -> 173336 | H8: =D8-C8 -> 53318 | I8: =H8/1000 -> 53.318 | K8: E7 | L8: 2025-01-12 10:32:22.944364 | M8: 2025-01-12 10:32:25.395657 | N8: 2451.2756 | O8: It's Paris. | P8: Oui
A9: E8 | B9: 1736674571775 | C9: 1736674691794 | D9: 1736674815289 | E9: 1736674932435 | F9: =C9-B9 -> 120019 | G9: =D9-B9 -> 243514 | H9: =D9-C9 -> 123495 | I9: =H9/1000 -> 123.495 | K9: E8 | L9: 2025-01-12 10:38:23.569774 | M9: 2025-01-12 10:38:26.016939 | N9: 2447.1469 | O9: I'm sorry, I don't understand who you are talking to. This is an assistant, I am not sure I know who this person is asking you questions. | P9: Non
A10: E9 | B10: 1736674932445 | C10: 1736675052464 | D10: 1736675113351 | E10: 1736675293072 | F10: =C10-B10 -> 120019 | G10: =D10-B10 -> 180906 | H10: =D10-C10 -> 60887 | I10: =H10/1000 -> 60.887 | K10: E9 | L10: 2025-01-12 10:44:24.502682 | M10: 2025-01-12 10:44:26.946673 | N10: 2443.9731 | O10: The capital of France is Paris. | P10: Oui
A11: E10 | B11: 1736675293082 | C11: 1736675413101 | D11: 1736675473592 | E11: 1736675653688 | F11: =C11-B11 -> 120019 | G11: =D11-B11 -> 180510 | H11: =D11-C11 -> 60491 | I11: =H11/1000 -> 60.491 | K11: E10 | L11: 2025-01-12 10:50:24.808997 | M11: 2025-01-12 10:50:27.250326 | N11: 2441.3104 | O11: I'm not sure about that. | P11: Non
A12: E11 | B12: 1736675653699 | C12: 1736675773718 | D12: 1736675833925 | E12: 1736676014384 | F12: =C12-B12 -> 120019 | G12: =D12-B12 -> 180226 | H12: =D12-C12 -> 60207 | I12: =H12/1000 -> 60.207 | K12: E11 | L12: 2025-01-12 10:56:25.245975 | M12: 2025-01-12 10:56:27.712193 | N12: 2466.1989 | O12: There is no capital in France. | P12: Non
A13: E12 | B13: 1736676014395 | C13: 1736676134414 | D13: 1736676189936 | E13: 1736676374998 | F13: =C13-B13 -> 120019 | G13: =D13-B13 -> 175541 | H13: =D13-C13 -> 55522 | I13: =H13/1000 -> 55.522 | K13: E12 | L13: 2025-01-12 11:02:26.095909 | M13: 2025-01-12 11:02:28.544187 | N13: 2448.2591 | O13: It is Paris. | P13: Oui
... A22: E21 | B22: 1736679260211 | C22: 1736679380229 | D22: 1736679488908 | E22: 1736679620845 | F22: =C22-B22 -> 120018 | G22: =D22-B22 -> 228697 | H22: =D22-C22 -> 108679 | I22: =H22/1000 -> 108.679 | K22: E21 | L22: 2025-01-12 11:56:31.911328 | M22: 2025-01-12 11:56:34.353461 | N22: 2442.1148 | O22: I couldn't verify the information. The capital of France is Paris, but I could check if this matches any information you provided. | P22: Oui
K24: (Données du fichier AI_executions.log : instants, temps d'exécution et réponses de l'IA à la question « What is the capital in France? »)
A25: (On a prit ces données du fichier nommé AI_executions_on_sut16.log) | K25: Critère utilisé : réponse correcte (Oui) si l'IA indique que la capitale de la France est Paris.

Sheet Reponse
A1: Exercice 01
A2: 1.B\ Le temps d’exécution de l’IA est de 94,2 s. Il correspond à l’intervalle de puissance maximale compris entre 117 200 ms et 211 400 ms sur la courbe est donc de 94,2 secondes.
A3: Start of AI executions | C3: 1736672467122
A4: End of AI executions | C4: 1736672554340
A5: Le temps exacte c'est | C5: =(C4-C3)/1000 -> 87.218
A7: 1.C/
A9: Temps avant l'IA 1736672467122-1736672347104=120018 ms
A10: Temps apres L'IA 1736672707749-1736672554340=207236 ms
A11: donc on prens la puissance<120018 et puissance>207236 ms
A12: ce qui donne | B12: =AVERAGE('E2'!B2:B1202,'E2'!B2075:B3601) -> 0.29108284
A14: 1.D/
A15: On calcule la puissance moyanne due a L'IA seule
A16: entre 120018 ms et 207236 ms
A17: ce qui donne | B17: =AVERAGE('E2'!B1203:B2074)-B12 -> 0.39495156
A19: 1.E/
A20: On Calculer l'empreinte carbone de l'exécution de l'IA : Énergie consommée (kWh) × Facteur d'émission (gCO₂eq/kWh).
A21: E(Kwh)=(Pmoy*temps d'xuction)/3600 00 | D21: =B17*C5/3600/1000 -> 9.5685792e-06
A22: intentnsite carbonne en france c'est | D22: 32
A23: empreinte carbonne | C23: =D22*D21 -> 0.00030619453 | D23: gCO2eq
A24: donc avec son unite correcte | D24: =C23*1000 -> 0.30619453 | E24: mgCO2eq
A25: Réponse 1.E : empreinte carbone de l'exécution IA = | C25: =C23 -> 0.00030619453 | D25: gCO2eq (soit 0,306 mgCO2eq)
A26: Exercice 2
B27: E1
A28: Ligne dans Log | B28: =MATCH(B27,Log!$A$2:$A$22,0)+1 -> 2
A29: Début IA relatif (ms) | B29: =INDEX(Log!$F$1:$F$22,B28) -> 120026
A30: Fin IA relative (ms) | B30: =INDEX(Log!$G$1:$G$22,B28) -> 262379
A32: Nombre d'élémennt hors IA | B32: =COUNT('E1'!$A$2:$A$3601)-B33 -> 2177
A33: Nombre d'élément zvec IA | B33: =COUNTIFS('E1'!$A$2:$A$3601,">="&B29,'E1'!$A$2:$A$3601,"<="&B30) -> 1423
A34: Somme P Sans IA (W) | B34: =SUM('E1'!$B$2:$B$3601)-B35 -> 636.278
A35: Somme P IA (W) | B35: =SUMIFS('E1'!$B$2:$B$3601,'E1'!$A$2:$A$3601,">="&B29,'E1'!$A$2:$A$3601,"<="&B30) -> 989.93
A37: P moyenne sans IA (W) | B37: =IFERROR(B34/B32,"") -> 0.29227285
A38: P moyenne pendant IA (W) | B38: =IFERROR(B35/B33,"") -> 0.69566409
A39: P due à l'IA (W) = P(avec IA) − P(sans IA) global | B39: =IFERROR(B38-$B$307,"") -> 0.40446881
B41: E3
A42: Ligne dans Log | B42: =MATCH(B41,Log!$A$2:$A$22,0)+1 -> 4
A43: Début IA relatif (ms) | B43: =INDEX(Log!$F$1:$F$22,B42) -> 120018
A44: Fin IA relative (ms) | B44: =INDEX(Log!$G$1:$G$22,B42) -> 178500
A46: Nombre d'élémennt hors IA | B46: =COUNT('E3'!$A$2:$A$3601)-B47 -> 3015
A47: Nombre d'élément zvec IA | B47: =COUNTIFS('E3'!$A$2:$A$3601,">="&B43,'E3'!$A$2:$A$3601,"<="&B44) -> 585
A48: Somme P Sans IA (W) | B48: =SUM('E3'!$B$2:$B$3601)-B49 -> 877.462
...

Sheet E1
A1: Temps (ms) | B1: Puissance (W) | C1: Courant (mA) | D1: Tension (V)
A2: 0 | B2: 0.288 | C2: 375.2 | D2: 0.772
A3: 100 | B3: 0.286 | C3: 375.5 | D3: 0.76
A4: 200 | B4: 0.288 | C4: 375.3 | D4: 0.764
A5: 300 | B5: 0.288 | C5: 375.2 | D5: 0.772
A6: 400 | B6: 0.292 | C6: 375.4 | D6: 0.776
A7: 500 | B7: 0.288 | C7: 375.3 | D7: 0.768
A8: 600 | B8: 0.286 | C8: 375.3 | D8: 0.76
A9: 700 | B9: 0.282 | C9: 375.4 | D9: 0.752
A10: 800 | B10: 0.278 | C10: 375.2 | D10: 0.744
A11: 900 | B11: 0.276 | C11: 375.2 | D11: 0.736
A12: 1000 | B12: 0.278 | C12: 375.4 | D12: 0.74
A13: 1100 | B13: 0.278 | C13: 375.3 | D13: 0.74
... A3601: 359900 | B3601: 0.288 | C3601: 379.9 | D3601: 0.76

Sheet E2
A1: Temps (ms) | B1: Puissance (W) | C1: Courant (mA) | D1: Tension (V)
A2: 0 | B2: 0.288 | C2: 379.7 | D2: 0.756
A3: 100 | B3: 0.288 | C3: 379.6 | D3: 0.76
A4: 200 | B4: 0.292 | C4: 379.6 | D4: 0.764
A5: 300 | B5: 0.292 | C5: 379.9 | D5: 0.768
A6: 400 | B6: 0.292 | C6: 379.6 | D6: 0.768
A7: 500 | B7: 0.288 | C7: 379.6 | D7: 0.756
A8: 600 | B8: 0.292 | C8: 379.7 | D8: 0.748
A9: 700 | B9: 0.282 | C9: 379.6 | D9: 0.74
A10: 800 | B10: 0.278 | C10: 379.6 | D10: 0.732
A11: 900 | B11: 0.278 | C11: 379.6 | D11: 0.732
A12: 1000 | B12: 0.282 | C12: 379.6 | D12: 0.74
A13: 1100 | B13: 0.288 | C13: 379.6 | D13: 0.744
... A3601: 359900 | B3601: 0.278 | C3601: 378.2 | D3601: 0.732

Sheet E3
A1: Temps (ms) | B1: Puissance (W) | C1: Courant (mA) | D1: Tension (V)
A2: 0 | B2: 0.286 | C2: 378.6 | D2: 0.76
A3: 100 | B3: 0.282 | C3: 378.2 | D3: 0.748
A4: 200 | B4: 0.278 | C4: 378.3 | D4: 0.736
A5: 300 | B5: 0.276 | C5: 378.2 | D5: 0.732
A6: 400 | B6: 0.278 | C6: 378.2 | D6: 0.736
A7: 500 | B7: 0.282 | C7: 378.4 | D7: 0.744
A8: 600 | B8: 0.282 | C8: 378.3 | D8: 0.748
A9: 700 | B9: 0.314 | C9: 418.8 | D9: 0.752
A10: 800 | B10: 0.288 | C10: 378.2 | D10: 0.764
A11: 900 | B11: 0.292 | C11: 378.2 | D11: 0.768
A12: 1000 | B12: 0.292 | C12: 378.3 | D12: 0.772
A13: 1100 | B13: 0.288 | C13: 378.2 | D13: 0.764
... A3601: 359900 | B3601: 0.288 | C3601: 377.9 | D3601: 0.768

Sheet E4
A1: Temps (ms) | B1: Puissance (W) | C1: Courant (mA) | D1: Tension (V)
A2: 0 | B2: 0.282 | C2: 377.3 | D2: 0.748
A3: 100 | B3: 0.286 | C3: 377.4 | D3: 0.752
A4: 200 | B4: 0.288 | C4: 377.5 | D4: 0.76
A5: 300 | B5: 0.288 | C5: 377.6 | D5: 0.764
A6: 400 | B6: 0.292 | C6: 377.7 | D6: 0.768
A7: 500 | B7: 0.288 | C7: 377.7 | D7: 0.764
A8: 600 | B8: 0.286 | C8: 377.6 | D8: 0.752
A9: 700 | B9: 0.282 | C9: 377.4 | D9: 0.744
A10: 800 | B10: 0.276 | C10: 377.3 | D10: 0.732
A11: 900 | B11: 0.276 | C11: 377.3 | D11: 0.732
A12: 1000 | B12: 0.278 | C12: 377.3 | D12: 0.736
A13: 1100 | B13: 0.278 | C13: 377.3 | D13: 0.74
... A3601: 359900 | B3601: 0.288 | C3601: 377.7 | D3601: 0.764

Sheet E5
A1: Temps (ms) | B1: Puissance (W) | C1: Courant (mA) | D1: Tension (V)
A2: 0 | B2: 0.288 | C2: 377.6 | D2: 0.76
A3: 100 | B3: 0.288 | C3: 377.7 | D3: 0.744
A4: 200 | B4: 0.292 | C4: 390.2 | D4: 0.748
A5: 300 | B5: 0.292 | C5: 378.1 | D5: 0.752
A6: 400 | B6: 0.288 | C6: 377.8 | D6: 0.76
A7: 500 | B7: 0.288 | C7: 377.4 | D7: 0.764
A8: 600 | B8: 0.288 | C8: 377.4 | D8: 0.768
A9: 700 | B9: 0.292 | C9: 380.1 | D9: 0.768
A10: 800 | B10: 0.288 | C10: 377.5 | D10: 0.76
A11: 900 | B11: 0.286 | C11: 377.5 | D11: 0.752
A12: 1000 | B12: 0.282 | C12: 377.5 | D12: 0.744
A13: 1100 | B13: 0.278 | C13: 377.3 | D13: 0.736
... A3601: 359900 | B3601: 0.748 | C3601: 1068.3 | D3601: 0.7

Sheet E6
A1: Temps (ms) | B1: Puissance (W) | C1: Courant (mA) | D1: Tension (V)
A2: 0 | B2: 0.396 | C2: 515 | D2: 0.772
A3: 100 | B3: 0.386 | C3: 514.7 | D3: 0.748
A4: 200 | B4: 0.384 | C4: 514.3 | D4: 0.744
A5: 300 | B5: 0.38 | C5: 514.1 | D5: 0.736
A6: 400 | B6: 0.374 | C6: 513.9 | D6: 0.728
A7: 500 | B7: 0.37 | C7: 513.7 | D7: 0.72
A8: 600 | B8: 0.37 | C8: 513.5 | D8: 0.72
A9: 700 | B9: 0.374 | C9: 513.2 | D9: 0.728
A10: 800 | B10: 0.376 | C10: 513.2 | D10: 0.732
A11: 900 | B11: 0.376 | C11: 513 | D11: 0.736
A12: 1000 | B12: 0.384 | C12: 512.6 | D12: 0.74
A13: 1100 | B13: 0.38 | C13: 512.6 | D13: 0.744
... A3601: 359900 | B3601: 0.286 | C3601: 388.3 | D3601: 0.768

Sheet E7
A1: Temps (ms) | B1: Puissance (W) | C1: Courant (mA) | D1: Tension (V)
A2: 0 | B2: 0.298 | C2: 388.9 | D2: 0.764
A3: 100 | B3: 0.294 | C3: 388.5 | D3: 0.756
A4: 200 | B4: 0.298 | C4: 388.9 | D4: 0.748
A5: 300 | B5: 0.294 | C5: 395.9 | D5: 0.74
A6: 400 | B6: 0.286 | C6: 388.3 | D6: 0.732
A7: 500 | B7: 0.304 | C7: 424.2 | D7: 0.728
A8: 600 | B8: 0.286 | C8: 388.2 | D8: 0.736
A9: 700 | B9: 0.294 | C9: 388 | D9: 0.74
A10: 800 | B10: 0.288 | C10: 388.1 | D10: 0.744
A11: 900 | B11: 0.292 | C11: 388.1 | D11: 0.748
A12: 1000 | B12: 0.294 | C12: 388.7 | D12: 0.756
A13: 1100 | B13: 0.294 | C13: 388.3 | D13: 0.76
... A3601: 359900 | B3601: 0.292 | C3601: 387.1 | D3601: 0.768

Sheet E8
A1: Temps (ms) | B1: Puissance (W) | C1: Courant (mA) | D1: Tension (V)
A2: 0 | B2: 0.286 | C2: 379.2 | D2: 0.752
A3: 100 | B3: 0.286 | C3: 378.9 | D3: 0.756
A4: 200 | B4: 0.292 | C4: 378.9 | D4: 0.768
A5: 300 | B5: 0.292 | C5: 378.8 | D5: 0.768
A6: 400 | B6: 0.292 | C6: 379 | D6: 0.772
A7: 500 | B7: 0.292 | C7: 379 | D7: 0.768
A8: 600 | B8: 0.288 | C8: 379.3 | D8: 0.76
A9: 700 | B9: 0.286 | C9: 379.2 | D9: 0.752
A10: 800 | B10: 0.288 | C10: 387.4 | D10: 0.744
A11: 900 | B11: 0.278 | C11: 378.8 | D11: 0.736
A12: 1000 | B12: 0.282 | C12: 378.8 | D12: 0.74
A13: 1100 | B13: 0.282 | C13: 378.8 | D13: 0.74
... A3601: 359900 | B3601: 0.282 | C3601: 380.1 | D3601: 0.744

Sheet E9
A1: Temps (ms) | B1: Puissance (W) | C1: Courant (mA) | D1: Tension (V)
A2: 0 | B2: 0.292 | C2: 380.2 | D2: 0.768
A3: 100 | B3: 0.292 | C3: 380.1 | D3: 0.768
A4: 200 | B4: 0.288 | C4: 380.1 | D4: 0.756
A5: 300 | B5: 0.286 | C5: 380.2 | D5: 0.748
A6: 400 | B6: 0.282 | C6: 380.2 | D6: 0.74
A7: 500 | B7: 0.278 | C7: 380.1 | D7: 0.732
A8: 600 | B8: 0.282 | C8: 381.1 | D8: 0.736
A9: 700 | B9: 0.282 | C9: 380.2 | D9: 0.74
A10: 800 | B10: 0.282 | C10: 380.4 | D10: 0.744
A11: 900 | B11: 0.286 | C11: 380.1 | D11: 0.748
A12: 1000 | B12: 0.288 | C12: 380.2 | D12: 0.756
A13: 1100 | B13: 0.288 | C13: 380.1 | D13: 0.76
... A3601: 359900 | B3601: 0.282 | C3601: 377.8 | D3601: 0.744

Sheet E10
A1: Temps (ms) | B1: Puissance (W) | C1: Courant (mA) | D1: Tension (V)
A2: 0 | B2: 0.286 | C2: 377.3 | D2: 0.756
A3: 100 | B3: 0.276 | C3: 377.8 | D3: 0.732
A4: 200 | B4: 0.278 | C4: 377.9 | D4: 0.736
A5: 300 | B5: 0.278 | C5: 377.7 | D5: 0.74
A6: 400 | B6: 0.278 | C6: 377.8 | D6: 0.74
A7: 500 | B7: 0.282 | C7: 377.9 | D7: 0.748
A8: 600 | B8: 0.286 | C8: 377.9 | D8: 0.752
A9: 700 | B9: 0.288 | C9: 377.8 | D9: 0.76
A10: 800 | B10: 0.288 | C10: 377.8 | D10: 0.76
A11: 900 | B11: 0.294 | C11: 413.6 | D11: 0.764
A12: 1000 | B12: 0.292 | C12: 377.8 | D12: 0.772
A13: 1100 | B13: 0.294 | C13: 377.9 | D13: 0.768
... A3601: 359900 | B3601: 0.282 | C3601: 377.4 | D3601: 0.744

Sheet E11
A1: Temps (ms) | B1: Puissance (W) | C1: Courant (mA) | D1: Tension (V)
A2: 0 | B2: 0.292 | C2: 377.7 | D2: 0.768
A3: 100 | B3: 0.282 | C3: 377.4 | D3: 0.748
A4: 200 | B4: 0.304 | C4: 413.1 | D4: 0.736
A5: 300 | B5: 0.278 | C5: 377.3 | D5: 0.736
A6: 400 | B6: 0.278 | C6: 377.5 | D6: 0.74
A7: 500 | B7: 0.278 | C7: 377.3 | D7: 0.74
A8: 600 | B8: 0.282 | C8: 377.2 | D8: 0.748
A9: 700 | B9: 0.286 | C9: 377.3 | D9: 0.752
A10: 800 | B10: 0.288 | C10: 377.4 | D10: 0.76
A11: 900 | B11: 0.288 | C11: 378.7 | D11: 0.76
A12: 1000 | B12: 0.288 | C12: 377.3 | D12: 0.764
A13: 1100 | B13: 0.292 | C13: 377.3 | D13: 0.772
... A3601: 359900 | B3601: 0.278 | C3601: 377.1 | D3601: 0.74

Sheet E12
A1: Temps (ms) | B1: Puissance (W) | C1: Courant (mA) | D1: Tension (V)
A2: 0 | B2: 0.288 | C2: 377.1 | D2: 0.768
A3: 100 | B3: 0.286 | C3: 377.2 | D3: 0.76
A4: 200 | B4: 0.286 | C4: 377.3 | D4: 0.752
A5: 300 | B5: 0.282 | C5: 377.1 | D5: 0.744
A6: 400 | B6: 0.278 | C6: 377.1 | D6: 0.736
A7: 500 | B7: 0.278 | C7: 377.1 | D7: 0.736
A8: 600 | B8: 0.278 | C8: 377.1 | D8: 0.74
A9: 700 | B9: 0.278 | C9: 377.2 | D9: 0.74
A10: 800 | B10: 0.282 | C10: 377.1 | D10: 0.748
A11: 900 | B11: 0.286 | C11: 377.6 | D11: 0.756
A12: 1000 | B12: 0.286 | C12: 377.1 | D12: 0.76
A13: 1100 | B13: 0.288 | C13: 377.1 | D13: 0.768
... A3601: 359900 | B3601: 0.286 | C3601: 377 | D3601: 0.76

Sheet E13
A1: Temps (ms) | B1: Puissance (W) | C1: Courant (mA) | D1: Tension (V)
A2: 0 | B2: 0.286 | C2: 377 | D2: 0.756
A3: 100 | B3: 0.282 | C3: 377 | D3: 0.752
A4: 200 | B4: 0.282 | C4: 377 | D4: 0.772
A5: 300 | B5: 0.292 | C5: 377.3 | D5: 0.772
A6: 400 | B6: 0.288 | C6: 377 | D6: 0.764
A7: 500 | B7: 0.286 | C7: 377.1 | D7: 0.756
A8: 600 | B8: 0.282 | C8: 377 | D8: 0.748
A9: 700 | B9: 0.278 | C9: 377.2 | D9: 0.74
A10: 800 | B10: 0.278 | C10: 377 | D10: 0.74
A11: 900 | B11: 0.278 | C11: 377 | D11: 0.74
A12: 1000 | B12: 0.282 | C12: 377 | D12: 0.744
A13: 1100 | B13: 0.282 | C13: 377.1 | D13: 0.748
... A3601: 359900 | B3601: 0.282 | C3601: 376.8 | D3601: 0.748

Sheet E15
A1: Temps (ms) | B1: Puissance (W) | C1: Courant (mA) | D1: Tension (V)
A2: 0 | B2: 0.292 | C2: 385.9 | D2: 0.772
A3: 100 | B3: 0.292 | C3: 379.1 | D3: 0.768
A4: 200 | B4: 0.286 | C4: 377.7 | D4: 0.756
A5: 300 | B5: 0.282 | C5: 377.7 | D5: 0.748
A6: 400 | B6: 0.278 | C6: 377.6 | D6: 0.74
A7: 500 | B7: 0.278 | C7: 386.1 | D7: 0.736
A8: 600 | B8: 0.278 | C8: 377.5 | D8: 0.74
A9: 700 | B9: 0.282 | C9: 377.5 | D9: 0.744
A10: 800 | B10: 0.282 | C10: 377.6 | D10: 0.748
A11: 900 | B11: 0.286 | C11: 377.6 | D11: 0.752
A12: 1000 | B12: 0.286 | C12: 385.8 | D12: 0.756
A13: 1100 | B13: 0.288 | C13: 387.7 | D13: 0.76
... A3601: 359900 | B3601: 0.288 | C3601: 377.2 | D3601: 0.768

Sheet E14
A1: Temps (ms) | B1: Puissance (W) | C1: Courant (mA) | D1: Tension (V)
A2: 0 | B2: 0.298 | C2: 376.7 | D2: 0.788
A3: 100 | B3: 0.292 | C3: 376.8 | D3: 0.772
A4: 200 | B4: 0.288 | C4: 377 | D4: 0.768
A5: 300 | B5: 0.286 | C5: 377.1 | D5: 0.76
A6: 400 | B6: 0.282 | C6: 377.2 | D6: 0.748
A7: 500 | B7: 0.278 | C7: 377.2 | D7: 0.74
A8: 600 | B8: 0.302 | C8: 413 | D8: 0.732
A9: 700 | B9: 0.278 | C9: 376.9 | D9: 0.74
A10: 800 | B10: 0.282 | C10: 376.9 | D10: 0.744
A11: 900 | B11: 0.282 | C11: 376.8 | D11: 0.744
A12: 1000 | B12: 0.282 | C12: 378.5 | D12: 0.752
A13: 1100 | B13: 0.286 | C13: 382.8 | D13: 0.756
... A3601: 359900 | B3601: 0.292 | C3601: 377.5 | D3601: 0.772

Sheet E16
A1: Temps (ms) | B1: Puissance (W) | C1: Courant (mA) | D1: Tension (V)
A2: 0 | B2: 0.288 | C2: 377.5 | D2: 0.768
A3: 100 | B3: 0.286 | C3: 377.6 | D3: 0.76
A4: 200 | B4: 0.286 | C4: 377.7 | D4: 0.756
A5: 300 | B5: 0.282 | C5: 377.6 | D5: 0.744
A6: 400 | B6: 0.286 | C6: 377.2 | D6: 0.736
A7: 500 | B7: 0.278 | C7: 377.2 | D7: 0.74
A8: 600 | B8: 0.282 | C8: 379 | D8: 0.744
A9: 700 | B9: 0.282 | C9: 377.3 | D9: 0.744
A10: 800 | B10: 0.282 | C10: 377.3 | D10: 0.732
A11: 900 | B11: 0.294 | C11: 377.3 | D11: 0.736
A12: 1000 | B12: 0.286 | C12: 377.2 | D12: 0.74
A13: 1100 | B13: 0.282 | C13: 377.8 | D13: 0.744
... A3601: 359900 | B3601: 0.318 | C3601: 432.4 | D3601: 0.768

Sheet E17
A1: Temps (ms) | B1: Puissance (W) | C1: Courant (mA) | D1: Tension (V)
A2: 0 | B2: 0.328 | C2: 429.9 | D2: 0.764
A3: 100 | B3: 0.328 | C3: 430 | D3: 0.76
A4: 200 | B4: 0.322 | C4: 429.6 | D4: 0.748
A5: 300 | B5: 0.288 | C5: 387.3 | D5: 0.744
A6: 400 | B6: 0.278 | C6: 377.1 | D6: 0.736
A7: 500 | B7: 0.276 | C7: 377.2 | D7: 0.732
A8: 600 | B8: 0.278 | C8: 377.2 | D8: 0.736
A9: 700 | B9: 0.278 | C9: 377.2 | D9: 0.74
A10: 800 | B10: 0.286 | C10: 385.2 | D10: 0.744
A11: 900 | B11: 0.286 | C11: 377.4 | D11: 0.752
A12: 1000 | B12: 0.286 | C12: 412.9 | D12: 0.756
A13: 1100 | B13: 0.292 | C13: 377.1 | D13: 0.764
... A3601: 359900 | B3601: 0.278 | C3601: 377.5 | D3601: 0.736

Sheet E19
A1: Temps (ms) | B1: Puissance (W) | C1: Courant (mA) | D1: Tension (V)
A2: 0 | B2: 0.286 | C2: 377.4 | D2: 0.756
A3: 100 | B3: 0.288 | C3: 377.5 | D3: 0.768
A4: 200 | B4: 0.292 | C4: 377.5 | D4: 0.772
A5: 300 | B5: 0.292 | C5: 377.5 | D5: 0.772
A6: 400 | B6: 0.288 | C6: 377.5 | D6: 0.764
A7: 500 | B7: 0.288 | C7: 380 | D7: 0.756
A8: 600 | B8: 0.282 | C8: 377.5 | D8: 0.744
A9: 700 | B9: 0.278 | C9: 377.5 | D9: 0.736
A10: 800 | B10: 0.278 | C10: 377.5 | D10: 0.74
A11: 900 | B11: 0.282 | C11: 377.5 | D11: 0.744
A12: 1000 | B12: 0.288 | C12: 386 | D12: 0.744
A13: 1100 | B13: 0.282 | C13: 377.6 | D13: 0.748
... A3601: 359900 | B3601: 0.288 | C3601: 377.6 | D3601: 0.768

Sheet E18
A1: Temps (ms) | B1: Puissance (W) | C1: Courant (mA) | D1: Tension (V)
A2: 0 | B2: 0.292 | C2: 377.8 | D2: 0.772
A3: 100 | B3: 0.286 | C3: 379.1 | D3: 0.752
A4: 200 | B4: 0.282 | C4: 413.6 | D4: 0.74
A5: 300 | B5: 0.286 | C5: 377.9 | D5: 0.736
A6: 400 | B6: 0.278 | C6: 377.9 | D6: 0.74
A7: 500 | B7: 0.282 | C7: 377.4 | D7: 0.744
A8: 600 | B8: 0.282 | C8: 388.6 | D8: 0.748
A9: 700 | B9: 0.286 | C9: 377.5 | D9: 0.752
A10: 800 | B10: 0.286 | C10: 377.5 | D10: 0.756
A11: 900 | B11: 0.288 | C11: 377.5 | D11: 0.764
A12: 1000 | B12: 0.288 | C12: 377.5 | D12: 0.768
A13: 1100 | B13: 0.292 | C13: 396.2 | D13: 0.768
... A3601: 359900 | B3601: 0.292 | C3601: 377.8 | D3601: 0.768

Sheet E20
A1: Temps (ms) | B1: Puissance (W) | C1: Courant (mA) | D1: Tension (V)
A2: 0 | B2: 0.288 | C2: 377.5 | D2: 0.748
A3: 100 | B3: 0.286 | C3: 377.3 | D3: 0.752
A4: 200 | B4: 0.288 | C4: 377.6 | D4: 0.76
A5: 300 | B5: 0.288 | C5: 377.6 | D5: 0.764
A6: 400 | B6: 0.292 | C6: 377.6 | D6: 0.768
A7: 500 | B7: 0.292 | C7: 377.7 | D7: 0.768
A8: 600 | B8: 0.288 | C8: 377.4 | D8: 0.76
A9: 700 | B9: 0.286 | C9: 377.3 | D9: 0.752
A10: 800 | B10: 0.282 | C10: 377.5 | D10: 0.744
A11: 900 | B11: 0.278 | C11: 377.4 | D11: 0.736
A12: 1000 | B12: 0.276 | C12: 377.4 | D12: 0.732
A13: 1100 | B13: 0.278 | C13: 377.3 | D13: 0.736
... A3601: 359900 | B3601: 0.288 | C3601: 390.7 | D3601: 0.736

Sheet E21
A1: Temps (ms) | B1: Puissance (W) | C1: Courant (mA) | D1: Tension (V)
A2: 0 | B2: 0.282 | C2: 379.3 | D2: 0.74
A3: 100 | B3: 0.278 | C3: 379 | D3: 0.736
A4: 200 | B4: 0.282 | C4: 378.8 | D4: 0.74
A5: 300 | B5: 0.282 | C5: 378.9 | D5: 0.74
A6: 400 | B6: 0.282 | C6: 379 | D6: 0.748
A7: 500 | B7: 0.286 | C7: 378.9 | D7: 0.752
A8: 600 | B8: 0.286 | C8: 379 | D8: 0.756
A9: 700 | B9: 0.314 | C9: 414.6 | D9: 0.756
A10: 800 | B10: 0.298 | C10: 378.8 | D10: 0.764
A11: 900 | B11: 0.292 | C11: 378.7 | D11: 0.768
A12: 1000 | B12: 0.288 | C12: 378.8 | D12: 0.764
A13: 1100 | B13: 0.286 | C13: 378.8 | D13: 0.756
... A3601: 359900 | B3601: 0.304 | C3601: 379.4 | D3601: 0.768
